<?xml version="1.0"?>
<robot name="quadruped_9g_leg">
  <link name="base_link">
    <visual>
      <geometry>
        <box size="0.1 0.05 0.02"/>
      </geometry>
    </visual>
  </link>

  <link name="shoulder_link">
    <visual>
      <geometry>
        <cylinder length="0.035" radius="0.005"/>
      </geometry>
      <origin rpy="1.57075 0 0" xyz="0 -0.0175 0"/>
    </visual>
  </link>
  <joint name="shoulder_joint" type="revolute">
    <axis xyz="1 0 0"/>
    <limit effort="1000.0" lower="-1.57075" upper="1.57075" velocity="0.5"/>
    <parent link="base_link"/>
    <child link="shoulder_link"/>
    <origin xyz="0.05 -0.005 0"/>
  </joint>

  
  <link name="thigh_link">
    <visual>
      <geometry>
        <cylinder length="0.045" radius="0.005"/>
      </geometry>
      <origin rpy="0 0 0" xyz="0 0 -0.0225"/>
    </visual>
  </link>
  <joint name="elbow_joint" type="revolute">
    <axis xyz="0 1 0"/>
    <limit effort="1000.0" lower="-1.57075" upper="1.57075" velocity="0.5"/>
    <parent link="shoulder_link"/>
    <child link="thigh_link"/>
    <origin xyz="0 -0.035 0"/>
  </joint>

 
  <link name="shank_link">
    <visual>
      <geometry>
        <cylinder length="0.05" radius="0.005"/>
      </geometry>
      <origin rpy="0 0 0" xyz="0 0 -0.025"/>
    </visual>
  </link>
  <joint name="wrist_joint" type="revolute">
    <axis xyz="0 1 0"/>
    <limit effort="1000.0" lower="-1.57075" upper="1.57075" velocity="0.5"/>
    <parent link="thigh_link"/>
    <child link="shank_link"/>
    <origin xyz="0 0 -0.045"/>
  </joint>


</robot>
