<?xml version="1.0" ?>
<!-- =================================================================================== -->
<!-- |    This document was autogenerated by xacro from qleg.urdf.xacro                | -->
<!-- |    EDITING THIS FILE BY HAND IS NOT RECOMMENDED                                 | -->
<!-- =================================================================================== -->
<robot name="quadruped_9g" xmlns:xacro="http://ros.org/wiki/xacro">
  <material name="red">
    <color rgba="1 0 0 1"/>
  </material>
  <material name="white">
    <color rgba="1 1 1 1"/>
  </material>
  <link name="base_link">
    <visual>
      <geometry>
        <box size="0.1 0.05 0.02"/>
      </geometry>
      <material name="white"/>
    </visual>
    <inertial>
      <mass value="10"/>
      <inertia ixx="1.0" ixy="0.0" iyy="1.0" iyz="0.0" izz="1.0"/>
    </inertial>
  </link>
  <link name="shoulder_link_lf">
    <visual>
      <geometry>
        <cylinder length="0.035" radius="0.0025"/>
      </geometry>
      <origin rpy="1.57075 0 0" xyz="0 0.0175 0"/>
      <material name="red"/>
    </visual>
    <inertial>
      <mass value="2"/>
      <inertia ixx="1.0" ixy="0.0" iyy="1.0" iyz="0.0" izz="1.0"/>
    </inertial>
  </link>
  <joint name="shoulder_joint_lf" type="revolute">
    <axis xyz="1 0 0"/>
    <limit effort="1000.0" lower="-1.57075" upper="1.57075" velocity="0.5"/>
    <parent link="base_link"/>
    <child link="shoulder_link_lf"/>
    <origin xyz="0.05 0.005 0"/>
  </joint>
  <link name="thigh_link_lf">
    <visual>
      <geometry>
        <cylinder length="0.045" radius="0.0025"/>
      </geometry>
      <origin rpy="0 0 0" xyz="0 0 -0.0225"/>
      <material name="white"/>
    </visual>
    <inertial>
      <mass value="2"/>
      <inertia ixx="1.0" ixy="0.0" iyy="1.0" iyz="0.0" izz="1.0"/>
    </inertial>
  </link>
  <joint name="elbow_joint_lf" type="revolute">
    <axis xyz="0 1 0"/>
    <limit effort="1000.0" lower="-1.57075" upper="1.57075" velocity="0.5"/>
    <parent link="shoulder_link_lf"/>
    <child link="thigh_link_lf"/>
    <origin xyz="0 0.035 0"/>
  </joint>
  <link name="shank_link">
    <visual>
      <geometry>
        <cylinder length="0.05" radius="0.0025"/>
      </geometry>
      <origin rpy="0 0 0" xyz="0 0 -0.025"/>
      <material name="red"/>
    </visual>
    <inertial>
      <mass value="2"/>
      <inertia ixx="1.0" ixy="0.0" iyy="1.0" iyz="0.0" izz="1.0"/>
    </inertial>
  </link>
  <joint name="wrist_joint" type="revolute">
    <axis xyz="0 1 0"/>
    <limit effort="1000.0" lower="-1.57075" upper="1.57075" velocity="0.5"/>
    <parent link="thigh_link_lf"/>
    <child link="shank_link_lf"/>
    <origin xyz="0 0 -0.045"/>
  </joint>
  <link name="shoulder_link_rf">
    <visual>
      <geometry>
        <cylinder length="0.035" radius="0.0025"/>
      </geometry>
      <origin rpy="1.57075 0 0" xyz="0 -0.0175 0"/>
      <material name="red"/>
    </visual>
    <inertial>
      <mass value="2"/>
      <inertia ixx="1.0" ixy="0.0" iyy="1.0" iyz="0.0" izz="1.0"/>
    </inertial>
  </link>
  <joint name="shoulder_joint_rf" type="revolute">
    <axis xyz="1 0 0"/>
    <limit effort="1000.0" lower="-1.57075" upper="1.57075" velocity="0.5"/>
    <parent link="base_link"/>
    <child link="shoulder_link_rf"/>
    <origin xyz="0.05 -0.005 0"/>
  </joint>
  <link name="thigh_link_rf">
    <visual>
      <geometry>
        <cylinder length="0.045" radius="0.0025"/>
      </geometry>
      <origin rpy="0 0 0" xyz="0 0 -0.0225"/>
      <material name="white"/>
    </visual>
    <inertial>
      <mass value="2"/>
      <inertia ixx="1.0" ixy="0.0" iyy="1.0" iyz="0.0" izz="1.0"/>
    </inertial>
  </link>
  <joint name="elbow_joint_rf" type="revolute">
    <axis xyz="0 1 0"/>
    <limit effort="1000.0" lower="-1.57075" upper="1.57075" velocity="0.5"/>
    <parent link="shoulder_link_rf"/>
    <child link="thigh_link_rf"/>
    <origin xyz="0 -0.035 0"/>
  </joint>
  <link name="shank_link">
    <visual>
      <geometry>
        <cylinder length="0.05" radius="0.0025"/>
      </geometry>
      <origin rpy="0 0 0" xyz="0 0 -0.025"/>
      <material name="red"/>
    </visual>
    <inertial>
      <mass value="2"/>
      <inertia ixx="1.0" ixy="0.0" iyy="1.0" iyz="0.0" izz="1.0"/>
    </inertial>
  </link>
  <joint name="wrist_joint" type="revolute">
    <axis xyz="0 1 0"/>
    <limit effort="1000.0" lower="-1.57075" upper="1.57075" velocity="0.5"/>
    <parent link="thigh_link_rf"/>
    <child link="shank_link_rf"/>
    <origin xyz="0 0 -0.045"/>
  </joint>
  <link name="shoulder_link_lb">
    <visual>
      <geometry>
        <cylinder length="0.035" radius="0.0025"/>
      </geometry>
      <origin rpy="1.57075 0 0" xyz="0 0.0175 0"/>
      <material name="red"/>
    </visual>
    <inertial>
      <mass value="2"/>
      <inertia ixx="1.0" ixy="0.0" iyy="1.0" iyz="0.0" izz="1.0"/>
    </inertial>
  </link>
  <joint name="shoulder_joint_lb" type="revolute">
    <axis xyz="1 0 0"/>
    <limit effort="1000.0" lower="-1.57075" upper="1.57075" velocity="0.5"/>
    <parent link="base_link"/>
    <child link="shoulder_link_lb"/>
    <origin xyz="-0.05 0.005 0"/>
  </joint>
  <link name="thigh_link_lb">
    <visual>
      <geometry>
        <cylinder length="0.045" radius="0.0025"/>
      </geometry>
      <origin rpy="0 0 0" xyz="0 0 -0.0225"/>
      <material name="white"/>
    </visual>
    <inertial>
      <mass value="2"/>
      <inertia ixx="1.0" ixy="0.0" iyy="1.0" iyz="0.0" izz="1.0"/>
    </inertial>
  </link>
  <joint name="elbow_joint_lb" type="revolute">
    <axis xyz="0 1 0"/>
    <limit effort="1000.0" lower="-1.57075" upper="1.57075" velocity="0.5"/>
    <parent link="shoulder_link_lb"/>
    <child link="thigh_link_lb"/>
    <origin xyz="0 0.035 0"/>
  </joint>
  <link name="shank_link">
    <visual>
      <geometry>
        <cylinder length="0.05" radius="0.0025"/>
      </geometry>
      <origin rpy="0 0 0" xyz="0 0 -0.025"/>
      <material name="red"/>
    </visual>
    <inertial>
      <mass value="2"/>
      <inertia ixx="1.0" ixy="0.0" iyy="1.0" iyz="0.0" izz="1.0"/>
    </inertial>
  </link>
  <joint name="wrist_joint" type="revolute">
    <axis xyz="0 1 0"/>
    <limit effort="1000.0" lower="-1.57075" upper="1.57075" velocity="0.5"/>
    <parent link="thigh_link_lb"/>
    <child link="shank_link_lb"/>
    <origin xyz="0 0 -0.045"/>
  </joint>
  <link name="shoulder_link_rb">
    <visual>
      <geometry>
        <cylinder length="0.035" radius="0.0025"/>
      </geometry>
      <origin rpy="1.57075 0 0" xyz="0 -0.0175 0"/>
      <material name="red"/>
    </visual>
    <inertial>
      <mass value="2"/>
      <inertia ixx="1.0" ixy="0.0" iyy="1.0" iyz="0.0" izz="1.0"/>
    </inertial>
  </link>
  <joint name="shoulder_joint_rb" type="revolute">
    <axis xyz="1 0 0"/>
    <limit effort="1000.0" lower="-1.57075" upper="1.57075" velocity="0.5"/>
    <parent link="base_link"/>
    <child link="shoulder_link_rb"/>
    <origin xyz="-0.05 -0.005 0"/>
  </joint>
  <link name="thigh_link_rb">
    <visual>
      <geometry>
        <cylinder length="0.045" radius="0.0025"/>
      </geometry>
      <origin rpy="0 0 0" xyz="0 0 -0.0225"/>
      <material name="white"/>
    </visual>
    <inertial>
      <mass value="2"/>
      <inertia ixx="1.0" ixy="0.0" iyy="1.0" iyz="0.0" izz="1.0"/>
    </inertial>
  </link>
  <joint name="elbow_joint_rb" type="revolute">
    <axis xyz="0 1 0"/>
    <limit effort="1000.0" lower="-1.57075" upper="1.57075" velocity="0.5"/>
    <parent link="shoulder_link_rb"/>
    <child link="thigh_link_rb"/>
    <origin xyz="0 -0.035 0"/>
  </joint>
  <link name="shank_link">
    <visual>
      <geometry>
        <cylinder length="0.05" radius="0.0025"/>
      </geometry>
      <origin rpy="0 0 0" xyz="0 0 -0.025"/>
      <material name="red"/>
    </visual>
    <inertial>
      <mass value="2"/>
      <inertia ixx="1.0" ixy="0.0" iyy="1.0" iyz="0.0" izz="1.0"/>
    </inertial>
  </link>
  <joint name="wrist_joint" type="revolute">
    <axis xyz="0 1 0"/>
    <limit effort="1000.0" lower="-1.57075" upper="1.57075" velocity="0.5"/>
    <parent link="thigh_link_rb"/>
    <child link="shank_link_rb"/>
    <origin xyz="0 0 -0.045"/>
  </joint>
</robot>

